<?xml version="1.0" ?>
<!-- =================================================================================== -->
<!-- |    This document was autogenerated by xacro from robot.urdf.xacro               | -->
<!-- |    EDITING THIS FILE BY HAND IS NOT RECOMMENDED                                 | -->
<!-- =================================================================================== -->
<robot name="sheldon_robot" xmlns:xacro="http://ros.org/wiki/xacro">
  <!-- from bottom of torso -->
  <!-- rotation  -->
  <!-- rotation from straight down ~28.5 deg -->
  <!-- rotation from straight down ~28.5 deg -->
  <!-- Include all component files -->
  <!-- Put all the color definitions in a separate file -->
  <material name="Black">
    <color rgba="0.2 0.2 0.2 1.0"/>
  </material>
  <material name="TransparentBlack">
    <color rgba="0.2 0.2 0.2 0.8"/>
  </material>
  <material name="Grey">
    <color rgba="0.7 0.7 0.7 1.0"/>
  </material>
  <material name="DarkGrey">
    <color rgba="0.3 0.3 0.3 1.0"/>
  </material>
  <material name="White">
    <color rgba="1.0 1.0 1.0 1.0"/>
  </material>
  <material name="OffWhite">
    <color rgba="0.8 0.8 0.8 1.0"/>
  </material>
  <material name="Red">
    <color rgba="0.8 0.0 0.0 1.0"/>
  </material>
  <material name="LightRed">
    <color rgba="0.8 0.4 0.4 1.0"/>
  </material>
  <material name="Aqua">
    <color rgba="0.1 0.7 0.7 1.0"/>
  </material>
  <material name="Blue">
    <color rgba="0.0 0.0 0.8 1.0"/>
  </material>
  <material name="LightBlue">
    <color rgba="0.7 0.7 1.0 1.0"/>
  </material>
  <material name="Green">
    <color rgba="0.0 0.8 0.0 1.0"/>
  </material>
  <material name="LightGreen">
    <color rgba="0.7 1.0 0.7 1.0"/>
  </material>
  <material name="TransparentGreen">
    <color rgba="0.0 0.8 0.0 0.5"/>
  </material>
  <material name="Orange">
    <color rgba="1.0  0.55 0.0 1.0"/>
  </material>
  <material name="Mustard">
    <color rgba="0.66 0.66 0 1.0"/>
  </material>
  <material name="Yellow">
    <color rgba="1.0 1.0 0 1.0"/>
  </material>
  <material name="Purple">
    <color rgba="0.66 0.33 1.0 1.0"/>
  </material>
  <!-- Sheldon Base definition. 
       base_link is centered between wheels, at ground level.
       All component positions are calculated relative to base_link  -->
  <!-- distance from ground to top of base -->
  <!-- "base_footprint" is the shadow the robot casts on the ground, for object avoidance -->
  <link name="base_footprint">
    <visual>
      <origin rpy="0 0 0" xyz="0 0 0"/>
      <geometry>
        <box size="0.559 0.366 0.001"/>
      </geometry>
      <material name="Black"/>
    </visual>
  </link>
  <joint name="base_joint" type="fixed">
    <origin rpy="0 0 0" xyz="0 0 0"/>
    <parent link="base_footprint"/>
    <child link="base_link"/>
  </joint>
  <!-- Base mounted laser -->
  <!-- Base to laser link 
    <joint name="base_laser_joint" type="fixed">
      <origin xyz="${base_laser_x} 0 ${base_laser_z}" rpy="0 0 0" />
      <parent link="base_link"/>
      <child link="laser_link"/>
    </joint>
    -->
  <!-- Laser definition 
    <link name="laser_link">
      <visual>
        <origin xyz="0 0 ${laser_height/2}" rpy="0 0 0" />
        <geometry>
          <cylinder length="${laser_height}" radius="${laser_radius}"/>
        </geometry>
        <material name="Red" /> 
      </visual>
    </link>
    -->
  <joint name="lidar_base_joint" type="fixed">
    <origin rpy="0 0 0" xyz="0.15 0 0.185"/>
    <parent link="base_link"/>
    <child link="lidar_base_link"/>
  </joint>
  <link name="lidar_base_link">
    <visual>
      <geometry>
        <cylinder length="0.022" radius="0.038"/>
      </geometry>
      <material name="Green"/>
      <origin rpy="0.0 0.0 0.0" xyz="0.0 0.0 0.011"/>
    </visual>
    <inertial>
      <mass value="0.000001"/>
      <origin xyz="0 0 0"/>
      <inertia ixx="0.0001" ixy="0.0" ixz="0.0" iyy="0.0001" iyz="0.0" izz="0.0001"/>
    </inertial>
  </link>
  <joint name="lidar_top_joint" type="fixed">
    <origin rpy="0.0 0.0 3.14159265359" xyz="0.0 0.0 0.028"/>
    <parent link="lidar_base_link"/>
    <child link="lidar_link"/>
  </joint>
  <link name="lidar_link">
    <visual>
      <geometry>
        <cylinder length="0.012" radius="0.038"/>
      </geometry>
      <material name="Red"/>
    </visual>
    <inertial>
      <mass value="0.000001"/>
      <origin xyz="0 0 0"/>
      <inertia ixx="0.0001" ixy="0.0" ixz="0.0" iyy="0.0001" iyz="0.0" izz="0.0001"/>
    </inertial>
  </link>
  <!-- distance above ground -->
  <!-- .294 (measured height) - base_deck_top -->
  <!-- velocity limit -->
  <!-- knee sits on top of tibia -->
  <!-- .575 (measured height) - .294 (tibia height) -->
  <!-- velocity limit -->
  <!-- hip sits on top of femur -->
  <!--  to top of shoulder .5112 .7112 28 inch torso for now -->
  <!-- rotation  -->
  <!-- KLUDGE FOR TESTING!!! -->
  <!--  -0.008 wrist center is slightly behind forearm center  -->
  <!-- "base_link" is the origin that all other componets are measured from -->
  <link name="base_link">
    <visual>
      <origin rpy="0 0 0" xyz="-0.025 0 0.088"/>
      <geometry>
        <mesh filename="package://sheldon_description/meshes/sheldon_base.stl" scale="0.1 0.1 0.1"/>
      </geometry>
      <material name="White"/>
    </visual>
    <collision>
      <origin rpy="0 0 0" xyz="0 0 0.0925"/>
      <geometry>
        <box size="0.559 0.366 0.185"/>
      </geometry>
    </collision>
  </link>
  <joint name="base_l_wheel_joint" type="fixed">
    <axis xyz="0 0 1"/>
    <limit effort="100" velocity="100"/>
    <safety_controller k_velocity="10"/>
    <origin rpy="1.57 0 0" xyz="-0.19 0.2032 0.0762"/>
    <parent link="base_link"/>
    <child link="base_l_wheel_link"/>
  </joint>
  <link name="base_l_wheel_link">
    <visual>
      <origin rpy="0 0 0" xyz="0 0 0"/>
      <geometry>
        <cylinder length="0.0508" radius="0.0762"/>
      </geometry>
      <material name="DarkGrey"/>
    </visual>
    <collision>
      <origin rpy="0 0 0" xyz="0 0 0"/>
      <geometry>
        <box size="0.1905 0.1905 0.0508"/>
        <!-- padding for wheel covers -->
      </geometry>
    </collision>
  </link>
  <joint name="base_r_wheel_joint" type="fixed">
    <axis xyz="0 0 1"/>
    <limit effort="100" velocity="100"/>
    <safety_controller k_velocity="10"/>
    <origin rpy="-1.57 0 0" xyz="-0.19 -0.2032 0.0762"/>
    <parent link="base_link"/>
    <child link="base_r_wheel_link"/>
  </joint>
  <link name="base_r_wheel_link">
    <visual>
      <origin rpy="0 0 0" xyz="0 0 0"/>
      <geometry>
        <cylinder length="0.0508" radius="0.0762"/>
      </geometry>
      <material name="DarkGrey"/>
    </visual>
    <collision>
      <origin rpy="0 0 0" xyz="0 0 0"/>
      <geometry>
        <box size="0.1905 0.1905 0.0508"/>
        <!-- padding for wheel covers -->
      </geometry>
    </collision>
  </link>
  <!-- Base to lower leg link -->
  <joint name="base_body_joint" type="fixed">
    <origin rpy="0 0 0" xyz="0.0 0.0 0.185"/>
    <parent link="base_link"/>
    <child link="tibia_link"/>
  </joint>
  <!-- Lower leg definition -->
  <link name="tibia_link">
    <visual>
      <origin rpy="0 0 0" xyz="0 0 0"/>
      <!--z =  -0.007 -->
      <geometry>
        <mesh filename="package://sheldon_description/meshes/sheldon_lower_legs.stl" scale="0.1 0.1 0.1"/>
      </geometry>
      <material name="Green"/>
    </visual>
    <collision>
      <origin rpy="0 0 0" xyz="0 0 0.0545"/>
      <geometry>
        <box size="0.0726 0.322 0.109"/>
      </geometry>
    </collision>
  </link>
  <joint name="knee_joint" type="revolute">
    <origin rpy="0 0 0" xyz="0 0  0.109"/>
    <axis xyz="0 -1 0"/>
    <limit effort="1.0" lower="-0.175" upper="0.873" velocity="1.571"/>
    <parent link="tibia_link"/>
    <child link="femur_link"/>
  </joint>
  <!-- Upper leg definition -->
  <link name="femur_link">
    <visual>
      <origin rpy="0 0 0.055" xyz="0 0 0"/>
      <!-- z = 0.025-->
      <geometry>
        <mesh filename="package://sheldon_description/meshes/sheldon_upper_legs.stl" scale="0.1 0.1 0.1"/>
      </geometry>
      <material name="Blue"/>
    </visual>
    <collision>
      <origin rpy="0 0 0" xyz="0 0 0.1405"/>
      <geometry>
        <box size="0.072 0.34 0.281"/>
      </geometry>
    </collision>
  </link>
  <joint name="hip_joint" type="revolute">
    <origin rpy="0 0 0" xyz="0 0  0.281"/>
    <axis xyz="0 1 0"/>
    <limit effort="1.0" lower="-0.175" upper="1.92" velocity="1.571"/>
    <parent link="femur_link"/>
    <child link="torso_link"/>
  </joint>
  <link name="torso_link">
    <visual>
      <origin rpy="0 0 0" xyz="0 0 0"/>
      <geometry>
        <mesh filename="package://sheldon_description/meshes/sheldon_torso.stl" scale="0.1 0.1 0.1"/>
      </geometry>
      <material name="LightBlue"/>
    </visual>
    <collision>
      <origin rpy="0 0 0" xyz="0 0 0.2285"/>
      <geometry>
        <box size="0.23 0.355 0.457"/>
      </geometry>
    </collision>
  </link>
  <!-- Head Link -->
  <link name="head_torso_link"/>
  <joint name="head_torso_joint" type="fixed">
    <origin rpy="0 0 3.14159" xyz="0.015 0.0 0.44"/>
    <parent link="torso_link"/>
    <child link="head_torso_link"/>
  </joint>
  <joint name="head_pan_servo_joint" type="fixed">
    <origin rpy="0 0 3.14" xyz="0 0 0"/>
    <parent link="head_torso_link"/>
    <child link="head_pan_servo_link"/>
  </joint>
  <link name="head_pan_servo_link">
    <inertial>
      <mass value="0.00001"/>
      <origin xyz="0 0 0"/>
      <inertia ixx="1.0" ixy="0.0" ixz="0.0" iyy="1.0" iyz="0.0" izz="1.0"/>
    </inertial>
    <visual>
      <origin rpy="0 0 -1.57" xyz=" 0 0 0 "/>
      <geometry>
        <mesh filename="package://sheldon_description/meshes/rx28.stl" scale="1 1 1"/>
      </geometry>
      <material name="DarkGrey"/>
    </visual>
    <collision>
      <origin rpy="0 0 0" xyz="-0.0133 0.0 0"/>
      <geometry>
        <box size="0.0506 0.045 0.0356"/>
      </geometry>
    </collision>
  </link>
  <joint name="head_pan_joint" type="revolute">
    <origin rpy="0 0 0" xyz="0 0 0.020"/>
    <axis xyz="0 0 1"/>
    <limit effort="1000" lower="-1.57" upper="1.57" velocity="0.524"/>
    <parent link="head_pan_servo_link"/>
    <child link="head_pan_link"/>
  </joint>
  <link name="head_pan_link">
    <inertial>
      <mass value="0.00001"/>
      <origin xyz="0 0 0"/>
      <inertia ixx="1.0" ixy="0.0" ixz="0.0" iyy="1.0" iyz="0.0" izz="1.0"/>
    </inertial>
    <visual>
      <origin rpy="1.57 0 0" xyz=" 0 0 0 "/>
      <geometry>
        <mesh filename="package://sheldon_description/meshes/rx64-side-bracket.stl" scale="1 1 1"/>
      </geometry>
      <material name="Grey"/>
    </visual>
    <collision>
      <origin rpy="0 0 0" xyz="0.000 0 0.005"/>
      <geometry>
        <box size="0.037 0.037 0.010"/>
      </geometry>
    </collision>
  </link>
  <joint name="head_tilt_servo_joint" type="fixed">
    <origin rpy="0 -1.57 0" xyz="0 0 0.0526"/>
    <parent link="head_pan_link"/>
    <child link="head_tilt_servo_link"/>
  </joint>
  <link name="head_tilt_servo_link">
    <inertial>
      <mass value="0.00001"/>
      <origin xyz="0 0 0"/>
      <inertia ixx="1.0" ixy="0.0" ixz="0.0" iyy="1.0" iyz="0.0" izz="1.0"/>
    </inertial>
    <visual>
      <origin rpy="1.57 1.57 0" xyz=" 0 0 0 "/>
      <geometry>
        <mesh filename="package://sheldon_description/meshes/rx64.stl" scale="1 1 1"/>
      </geometry>
      <material name="DarkGrey"/>
    </visual>
    <collision>
      <origin rpy="0 0 0" xyz="-0.01755 0 0"/>
      <geometry>
        <box size="0.0611 0.0470 0.0420"/>
      </geometry>
    </collision>
  </link>
  <joint name="head_tilt_joint" type="revolute">
    <origin rpy="0 0 0" xyz="0 0 0"/>
    <axis xyz="0 1 0"/>
    <limit effort="1000" lower="-0.6" upper="1.2" velocity="0.524"/>
    <parent link="head_tilt_servo_link"/>
    <child link="head_tilt_link"/>
  </joint>
  <link name="head_tilt_link">
    <inertial>
      <mass value="0.00001"/>
      <origin xyz="0 0 0"/>
      <inertia ixx="1.0" ixy="0.0" ixz="0.0" iyy="1.0" iyz="0.0" izz="1.0"/>
    </inertial>
    <visual>
      <origin rpy="0 0 -1.57" xyz="0 0 0"/>
      <geometry>
        <mesh filename="package://sheldon_description/meshes/rx64-hinge-bracket.stl" scale="1 1 1"/>
      </geometry>
      <material name="Grey"/>
    </visual>
    <collision>
      <origin rpy="0 0 0" xyz="0.015 0.0 0.0"/>
      <geometry>
        <box size="0.030 0.056 0.031"/>
      </geometry>
    </collision>
  </link>
  <joint name="head_sidetilt_servo_joint" type="fixed">
    <origin rpy="-1.57 0 0" xyz="0.0686 0 0"/>
    <parent link="head_tilt_link"/>
    <child link="head_sidetilt_servo_link"/>
  </joint>
  <link name="head_sidetilt_servo_link">
    <inertial>
      <mass value="0.00001"/>
      <origin xyz="0 0 0"/>
      <inertia ixx="1.0" ixy="0.0" ixz="0.0" iyy="1.0" iyz="0.0" izz="1.0"/>
    </inertial>
    <visual>
      <origin rpy="1.57 1.57 0" xyz=" 0 0 0 "/>
      <geometry>
        <mesh filename="package://sheldon_description/meshes/rx28.stl" scale="1 1 1"/>
      </geometry>
      <material name="DarkGrey"/>
    </visual>
    <collision>
      <origin rpy="0 0 0" xyz="-0.0133 0 0"/>
      <geometry>
        <box size="0.0506 0.045 0.0356"/>
      </geometry>
    </collision>
  </link>
  <joint name="head_sidetilt_joint" type="revolute">
    <origin rpy="0 0 0" xyz="0 0 0"/>
    <axis xyz="0 1 0"/>
    <limit effort="1000" lower="-0.35" upper="0.35" velocity="0.524"/>
    <parent link="head_sidetilt_servo_link"/>
    <child link="head_sidetilt_link"/>
  </joint>
  <link name="head_sidetilt_link">
    <inertial>
      <mass value="0.00001"/>
      <origin xyz="0 0 0"/>
      <inertia ixx="1.0" ixy="0.0" ixz="0.0" iyy="1.0" iyz="0.0" izz="1.0"/>
    </inertial>
    <visual>
      <origin rpy="0 0 -1.57" xyz="0 0 0"/>
      <geometry>
        <mesh filename="package://sheldon_description/meshes/rx28-hinge-bracket.stl" scale="1 1 1"/>
      </geometry>
      <material name="Grey"/>
    </visual>
    <collision>
      <origin rpy="0 0 0" xyz="0.015 0.0 0.0"/>
      <geometry>
        <box size="0.030 0.045 0.031"/>
      </geometry>
    </collision>
  </link>
  <!-- Head -->
  <joint name="head_joint" type="fixed">
    <origin rpy="1.57 0 1.57" xyz="0 0 0"/>
    <parent link="head_sidetilt_link"/>
    <child link="head_link"/>
  </joint>
  <link name="head_link">
    <visual>
      <origin rpy="0 0 0" xyz="0 0 0"/>
      <geometry>
        <mesh filename="package://sheldon_description/meshes/sheldon_head.stl" scale="0.1 0.1 0.1"/>
      </geometry>
      <material name="LightRed"/>
    </visual>
    <collision>
      <origin rpy="0 0 0" xyz="0.05 -0.02 0"/>
      <geometry>
        <box size="0.18 0.22 0.24"/>
      </geometry>
    </collision>
  </link>
  <joint name="nuitrack_camera_joint" type="fixed">
    <origin rpy="0 0.16 0" xyz="0.05 0.0 0.025"/>
    <parent link="head_link"/>
    <child link="nuitrack_camera_link"/>
  </joint>
  <link name="nuitrack_camera_link">
    <visual>
      <origin rpy="1.57 0 1.57" xyz="0.03 0.02 0.085"/>
      <!-- rpy="0 0 -1.57"-->
      <geometry>
        <!-- </mesh filename="package://tb2s_description/meshes/xtion.stl" scale="0.001 0.001 0.001"/> -->
        <mesh filename="package://sheldon_description/meshes/astra.stl" scale="0.001 0.001 0.001"/>
      </geometry>
      <material name="Green"/>
    </visual>
    <collision>
      <origin rpy="0 0 0" xyz="0 0 0.032075"/>
      <geometry>
        <box size="0.0381 0.1793875 0.0254"/>
      </geometry>
    </collision>
  </link>
  <!-- Attach Astra camera in the head  
  <astra_camera name = "astra_camera2" parent = "head" color="Green">
     <origin xyz="${front_astra_camera_offset_x} ${front_astra_camera_offset_y} ${front_astra_camera_offset_z}" rpy="0 ${front_astra_camera_rotation} 0" /> 
  </astra_camera>
  -->
  <!-- Attach the front camera  
   <depth_camera camera_id="camera1" parent="torso" color="DarkGrey">
     <origin xyz="${front_depth_camera_offset_x} ${front_depth_camera_offset_y} ${front_depth_camera_offset_z}" rpy="${PI - front_depth_camera_rotation} 0 ${PI/2}" /> 
   </depth_camera> 
-->
  <!-- Attach the rear camera  
   <depth_camera camera_id="camera2" parent="torso" color="DarkGrey">
     <origin xyz="${rear_depth_camera_offset_x} ${rear_depth_camera_offset_y} ${rear_depth_camera_offset_z}" rpy="${PI - rear_depth_camera_rotation} 0 ${-PI/2}" /> 
   </depth_camera>  
-->
  <joint name="astra_camera_joint" type="fixed">
    <origin rpy="0 0.0 0" xyz="0.1 0.0 0.38"/>
    <parent link="torso_link"/>
    <child link="astra_camera_link"/>
  </joint>
  <link name="astra_camera_link">
    <visual>
      <origin rpy="1.57 0 1.57" xyz="0.03 0.02 0.085"/>
      <!-- rpy="0 0 -1.57"-->
      <geometry>
        <!-- </mesh filename="package://tb2s_description/meshes/xtion.stl" scale="0.001 0.001 0.001"/> -->
        <mesh filename="package://sheldon_description/meshes/astra.stl" scale="0.001 0.001 0.001"/>
      </geometry>
      <material name="Green"/>
    </visual>
    <collision>
      <origin rpy="0 0 0" xyz="0 0 0.032075"/>
      <geometry>
        <box size="0.0381 0.1793875 0.0254"/>
      </geometry>
    </collision>
  </link>
  <!--
   <sensor_lplidar parent = "base">
      <origin xyz="0.00 0.0 0.0" rpy="0.0 0.0 0.0" /> 
   </sensor_lplidar>
-->
  <link name="right_arm_torso_link"/>
  <joint name="right_arm_torso_joint" type="fixed">
    <origin rpy="0 0 0" xyz="0.0 -0.164 0.389"/>
    <parent link="torso_link"/>
    <child link="right_arm_torso_link"/>
  </joint>
  <joint name="right_arm_shoulder_rotate_servo_joint" type="fixed">
    <origin rpy="3.14 -1.57 0" xyz="0 0 0"/>
    <parent link="right_arm_torso_link"/>
    <child link="right_arm_shoulder_rotate_servo_link"/>
  </joint>
  <link name="right_arm_shoulder_rotate_servo_link">
    <inertial>
      <mass value="0.00001"/>
      <origin xyz="0 0 0"/>
      <inertia ixx="1.0" ixy="0.0" ixz="0.0" iyy="1.0" iyz="0.0" izz="1.0"/>
    </inertial>
    <visual>
      <origin rpy="1.57 1.57 0" xyz=" 0 0 0 "/>
      <geometry>
        <mesh filename="package://sheldon_description/meshes/rx64.stl" scale="1 1 1"/>
      </geometry>
      <material name="Green"/>
    </visual>
    <collision>
      <origin rpy="0 0 0" xyz="-0.01755 0 0"/>
      <geometry>
        <box size="0.0611 0.0470 0.0420"/>
      </geometry>
    </collision>
  </link>
  <joint name="right_arm_shoulder_rotate_joint" type="revolute">
    <origin rpy="-1.57 0 1.57" xyz="0 0 0"/>
    <axis xyz="1 0 0"/>
    <limit effort="1000" lower="-3.14" upper="3.14" velocity="2.3"/>
    <parent link="right_arm_shoulder_rotate_servo_link"/>
    <child link="right_arm_shoulder_rotate_link"/>
  </joint>
  <link name="right_arm_shoulder_rotate_link">
    <inertial>
      <mass value="0.00001"/>
      <origin xyz="0 0 0"/>
      <inertia ixx="1.0" ixy="0.0" ixz="0.0" iyy="1.0" iyz="0.0" izz="1.0"/>
    </inertial>
    <visual>
      <origin rpy="-1.57 0 3.14" xyz="0.0869955 0 0"/>
      <geometry>
        <mesh filename="package://sheldon_description/meshes/sixdof_bracket2.stl" scale="0.001 0.001 0.001"/>
      </geometry>
      <material name="Grey"/>
    </visual>
    <collision>
      <origin rpy="0 0 0" xyz="0.0381 0.0 0.0"/>
      <geometry>
        <box size="0.0762 0.053 0.044"/>
      </geometry>
    </collision>
  </link>
  <!-- Shoulder Lift -->
  <joint name="right_arm_shoulder_lift_joint" type="revolute">
    <origin rpy="0 0 0" xyz="0.0869955 0 0"/>
    <axis xyz="0 1 0"/>
    <limit effort="1000" lower="-0.050" upper="2.10" velocity="4.6"/>
    <parent link="right_arm_shoulder_rotate_link"/>
    <child link="right_arm_shoulder_lift_servo_link"/>
  </joint>
  <link name="right_arm_shoulder_lift_servo_link">
    <inertial>
      <mass value="0.00001"/>
      <origin xyz="0 0 0"/>
      <inertia ixx="1.0" ixy="0.0" ixz="0.0" iyy="1.0" iyz="0.0" izz="1.0"/>
    </inertial>
    <visual>
      <origin rpy="1.57 -3.14 0" xyz=" 0 0 0 "/>
      <!-- rpy="1.57 -1.57 0" or -3.14 -->
      <geometry>
        <mesh filename="package://sheldon_description/meshes/rx64.stl" scale="1 1 1"/>
      </geometry>
      <material name="Green"/>
    </visual>
    <collision>
      <origin rpy="0 0 0" xyz="0.01755 0 0"/>
      <geometry>
        <box size="0.0611 0.0470 0.0420"/>
      </geometry>
    </collision>
  </link>
  <!-- Upper Arm fixed link -->
  <joint name="right_arm_upper_fixed_joint" type="fixed">
    <origin rpy="0 -1.57 0" xyz="0 0 0"/>
    <parent link="right_arm_shoulder_lift_servo_link"/>
    <child link="right_arm_upper_link"/>
  </joint>
  <link name="right_arm_upper_link">
    <inertial>
      <mass value="0.00001"/>
      <origin xyz="0 0 0"/>
      <inertia ixx="1.0" ixy="0.0" ixz="0.0" iyy="1.0" iyz="0.0" izz="1.0"/>
    </inertial>
    <visual>
      <origin rpy="0 -1.57 0.0" xyz="0 0 0"/>
      <geometry>
        <mesh filename="package://sheldon_description/meshes/sheldon_right_arm_upper.stl" scale="0.1 0.1 0.1"/>
      </geometry>
      <material name="Mustard"/>
    </visual>
    <collision>
      <origin rpy="0 0 0" xyz="0.1925 0 0 "/>
      <geometry>
        <box size="0.305 0.09 0.09"/>
      </geometry>
    </collision>
  </link>
  <joint name="right_arm_elbow_rotate_servo_joint" type="fixed">
    <origin rpy="-1.57 0.0 -1.57" xyz="0.335 -0.015 0"/>
    <parent link="right_arm_upper_link"/>
    <child link="right_arm_elbow_rotate_servo_link"/>
  </joint>
  <link name="right_arm_elbow_rotate_servo_link">
    <inertial>
      <mass value="0.00001"/>
      <origin xyz="0 0 0"/>
      <inertia ixx="1.0" ixy="0.0" ixz="0.0" iyy="1.0" iyz="0.0" izz="1.0"/>
    </inertial>
    <visual>
      <origin rpy="0 0 -1.57" xyz=" 0 0 0 "/>
      <geometry>
        <mesh filename="package://sheldon_description/meshes/rx64.stl" scale="1 1 1"/>
      </geometry>
      <material name="Blue"/>
    </visual>
    <collision>
      <origin rpy="0 0 0" xyz="-0.01755 0.0 0"/>
      <geometry>
        <box size="0.0611 0.0420 0.0470"/>
      </geometry>
    </collision>
  </link>
  <joint name="right_arm_elbow_rotate_joint" type="revolute">
    <origin rpy="0 0 0" xyz="0 0 0.0235"/>
    <axis xyz="0 0 1"/>
    <limit effort="1000" lower="-2.2" upper="3.14" velocity="6.6"/>
    <parent link="right_arm_elbow_rotate_servo_link"/>
    <child link="right_arm_elbow_rotate_link"/>
  </joint>
  <link name="right_arm_elbow_rotate_link">
    <inertial>
      <mass value="0.00001"/>
      <origin xyz="0 0 0"/>
      <inertia ixx="1.0" ixy="0.0" ixz="0.0" iyy="1.0" iyz="0.0" izz="1.0"/>
    </inertial>
    <visual>
      <origin rpy="1.57 0 0" xyz=" 0 0 0 "/>
      <geometry>
        <mesh filename="package://sheldon_description/meshes/rx64-side-bracket.stl" scale="1 1 1"/>
      </geometry>
      <material name="Grey"/>
    </visual>
    <collision>
      <origin rpy="0 0 0" xyz="0.000 0 0.005"/>
      <geometry>
        <box size="0.037 0.037 0.010"/>
      </geometry>
    </collision>
  </link>
  <joint name="right_arm_elbow_bend_servo_joint" type="fixed">
    <origin rpy="0 -1.57 0" xyz="0 0 0.0526"/>
    <parent link="right_arm_elbow_rotate_link"/>
    <child link="right_arm_elbow_bend_servo_link"/>
  </joint>
  <link name="right_arm_elbow_bend_servo_link">
    <inertial>
      <mass value="0.00001"/>
      <origin xyz="0 0 0"/>
      <inertia ixx="1.0" ixy="0.0" ixz="0.0" iyy="1.0" iyz="0.0" izz="1.0"/>
    </inertial>
    <visual>
      <origin rpy="1.57 1.57 0" xyz=" 0 0 0 "/>
      <geometry>
        <mesh filename="package://sheldon_description/meshes/rx64.stl" scale="1 1 1"/>
      </geometry>
      <material name="Green"/>
    </visual>
    <collision>
      <origin rpy="0 0 0" xyz="-0.01755 0 0"/>
      <geometry>
        <box size="0.0611 0.0470 0.0420"/>
      </geometry>
    </collision>
  </link>
  <joint name="right_arm_elbow_bend_joint" type="revolute">
    <origin rpy="0 0 0" xyz="0 0 0.0"/>
    <axis xyz="0 1 0"/>
    <limit effort="1000" lower="-1.2" upper="3.14" velocity="6.6"/>
    <parent link="right_arm_elbow_bend_servo_link"/>
    <child link="right_arm_elbow_bend_link"/>
  </joint>
  <link name="right_arm_elbow_bend_link">
    <inertial>
      <mass value="0.00001"/>
      <origin xyz="0 0 0"/>
      <inertia ixx="1.0" ixy="0.0" ixz="0.0" iyy="1.0" iyz="0.0" izz="1.0"/>
    </inertial>
    <visual>
      <origin rpy="0 0 -1.57" xyz="0 0 0"/>
      <geometry>
        <mesh filename="package://sheldon_description/meshes/rx64-hinge-bracket.stl" scale="1 1 1"/>
      </geometry>
      <material name="Grey"/>
    </visual>
    <collision>
      <origin rpy="0 0 0" xyz="0.015 0.0 0.0"/>
      <geometry>
        <box size="0.030 0.056 0.031"/>
      </geometry>
    </collision>
  </link>
  <!-- Lower Arm fixed link -->
  <joint name="right_arm_lower_fixed_joint" type="fixed">
    <!--  "0.030 0 0.031" half the length, plus bracket lenth and offset -->
    <origin rpy="0 1.57 0" xyz="0.030 0 0.031"/>
    <!-- KLUDGE FOR TESTING!!! -->
    <parent link="right_arm_elbow_bend_link"/>
    <child link="right_arm_lower_link"/>
  </joint>
  <link name="right_arm_lower_link">
    <inertial>
      <mass value="0.00001"/>
      <origin xyz="0 0 0"/>
      <inertia ixx="1.0" ixy="0.0" ixz="0.0" iyy="1.0" iyz="0.0" izz="1.0"/>
    </inertial>
    <visual>
      <origin rpy="0 0 0" xyz="0 0 0.0765"/>
      <!-- rpy="-1.57 0 0" -->
      <geometry>
        <!-- TODO: <mesh filename="package://sheldon_description/meshes/sheldon_${side}_lower.stl" scale="0.1 0.1 0.1"/> -->
        <box size="0.04 0.06 0.153"/>
      </geometry>
      <material name="Yellow"/>
    </visual>
    <collision>
      <origin rpy="0 0 0" xyz="0 0 0.0765"/>
      <!-- rpy="-1.57 0 0"   divide a little more then 1/2 for collision-->
      <geometry>
        <box size="0.04 0.06 0.1377"/>
      </geometry>
    </collision>
  </link>
  <joint name="right_arm_wrist_bend_servo_joint" type="fixed">
    <origin rpy="0 -1.57 0" xyz="0 0 0.1705"/>
    <parent link="right_arm_lower_link"/>
    <child link="right_arm_wrist_bend_servo_link"/>
  </joint>
  <link name="right_arm_wrist_bend_servo_link">
    <inertial>
      <mass value="0.00001"/>
      <origin xyz="0 0 0"/>
      <inertia ixx="1.0" ixy="0.0" ixz="0.0" iyy="1.0" iyz="0.0" izz="1.0"/>
    </inertial>
    <visual>
      <origin rpy="1.57 1.57 0" xyz=" 0 0 0 "/>
      <geometry>
        <mesh filename="package://sheldon_description/meshes/rx28.stl" scale="1 1 1"/>
      </geometry>
      <material name="Green"/>
    </visual>
    <collision>
      <origin rpy="0 0 0" xyz="-0.0133 0 0"/>
      <geometry>
        <box size="0.0506 0.045 0.0356"/>
      </geometry>
    </collision>
  </link>
  <joint name="right_arm_wrist_bend_joint" type="revolute">
    <origin rpy="0 0 0" xyz="0 0 0.0"/>
    <axis xyz="0 1 0"/>
    <limit effort="1000" lower="-1.57" upper="1.57" velocity="6.6"/>
    <parent link="right_arm_wrist_bend_servo_link"/>
    <child link="right_arm_wrist_bend_link"/>
  </joint>
  <link name="right_arm_wrist_bend_link">
    <inertial>
      <mass value="0.00001"/>
      <origin xyz="0 0 0"/>
      <inertia ixx="1.0" ixy="0.0" ixz="0.0" iyy="1.0" iyz="0.0" izz="1.0"/>
    </inertial>
    <visual>
      <origin rpy="0 0 -1.57" xyz="0 0 0"/>
      <geometry>
        <mesh filename="package://sheldon_description/meshes/rx28-hinge-bracket.stl" scale="1 1 1"/>
      </geometry>
      <material name="Grey"/>
    </visual>
    <collision>
      <origin rpy="0 0 0" xyz="0.015 0.0 0.0"/>
      <geometry>
        <box size="0.030 0.045 0.031"/>
      </geometry>
    </collision>
  </link>
  <joint name="right_arm_wrist_rotate_servo_joint" type="fixed">
    <origin rpy="3.14 -1.57 0" xyz="0.0475 0 0"/>
    <parent link="right_arm_wrist_bend_link"/>
    <child link="right_arm_wrist_rotate_servo_link"/>
  </joint>
  <link name="right_arm_wrist_rotate_servo_link">
    <inertial>
      <mass value="0.00001"/>
      <origin xyz="0 0 0"/>
      <inertia ixx="1.0" ixy="0.0" ixz="0.0" iyy="1.0" iyz="0.0" izz="1.0"/>
    </inertial>
    <visual>
      <origin rpy="0 0 -1.57" xyz=" 0 0 0 "/>
      <geometry>
        <mesh filename="package://sheldon_description/meshes/rx28.stl" scale="1 1 1"/>
      </geometry>
      <material name="Green"/>
    </visual>
    <collision>
      <origin rpy="0 0 0" xyz="-0.0133 0.0 0"/>
      <geometry>
        <box size="0.0506 0.045 0.0356"/>
      </geometry>
    </collision>
  </link>
  <joint name="right_arm_wrist_rotate_joint" type="revolute">
    <origin rpy="0 0 0" xyz="0 0 0"/>
    <axis xyz="0 0 1"/>
    <limit effort="1000" lower="-3.0" upper="1.57" velocity="5.8"/>
    <parent link="right_arm_wrist_rotate_servo_link"/>
    <child link="right_arm_wrist_rotate_link"/>
  </joint>
  <link name="right_arm_wrist_rotate_link">
    <inertial>
      <mass value="0.00001"/>
      <origin xyz="0 0 0"/>
      <inertia ixx="1.0" ixy="0.0" ixz="0.0" iyy="1.0" iyz="0.0" izz="1.0"/>
    </inertial>
    <visual>
      <origin rpy="1.57 0 0" xyz=" 0 0 0 "/>
      <geometry>
        <mesh filename="package://sheldon_description/meshes/rx28-side-bracket.stl" scale="1 1 1"/>
      </geometry>
      <material name="Grey"/>
    </visual>
    <collision>
      <origin rpy="0 0 0" xyz="0.005 0 0.005"/>
      <geometry>
        <box size="0.010 0.037 0.037"/>
      </geometry>
    </collision>
  </link>
  <!-- Gripper fixed joint -->
  <joint name="right_arm_gripper_fixed_joint" type="fixed">
    <origin rpy="0 0 0" xyz="0 0 0"/>
    <!-- "0 0.03 0" -->
    <parent link="right_arm_wrist_rotate_link"/>
    <child link="right_arm_gripper_body_link"/>
  </joint>
  <!-- Gripper body fixed link -->
  <link name="right_arm_gripper_body_link">
    <inertial>
      <mass value="0.00001"/>
      <origin xyz="0 0 0"/>
      <inertia ixx="1.0" ixy="0.0" ixz="0.0" iyy="1.0" iyz="0.0" izz="1.0"/>
    </inertial>
    <visual>
      <origin rpy="0 0 0" xyz="0 0 0"/>
      <!-- rpy="-1.57 0 0" -->
      <geometry>
        <mesh filename="package://sheldon_description/meshes/sheldon_claw.stl" scale="0.1 0.1 0.1"/>
        <!-- <box size="0.05 0.12 0.215"/> -->
      </geometry>
      <material name="Purple"/>
    </visual>
    <collision>
      <origin rpy="0 0 0" xyz="0 0 0.1075"/>
      <!-- rpy="-1.57 0 0" -->
      <geometry>
        <box size="0.05 0.09 0.170"/>
      </geometry>
    </collision>
  </link>
  <!-- Finger Rotate -->
  <joint name="right_arm_gripper_finger_joint" type="revolute">
    <axis xyz="1 0 0"/>
    <limit effort="1000" lower="-0.10" upper="3.14" velocity="5.8"/>
    <origin rpy="-0.20 0 0" xyz="0.0 -0.035 0.085"/>
    <parent link="right_arm_gripper_body_link"/>
    <child link="right_arm_gripper_finger_link1"/>
  </joint>
  <link name="right_arm_gripper_finger_link1">
    <visual>
      <origin rpy="0.0 0.0 0.0" xyz="0 -0.020 0.08"/>
      <geometry>
        <box size="0.02 0.02 0.08"/>
      </geometry>
      <material name="Mustard"/>
    </visual>
    <collision>
      <origin rpy="0.0 0.0 0.0" xyz="0 -0.020 0.08"/>
      <geometry>
        <box size="0.02 0.02 0.08"/>
      </geometry>
    </collision>
  </link>
  <joint name="right_arm_gripper_finger_joint2" type="revolute">
    <mimic joint="right_arm_gripper_finger_joint"/>
    <axis xyz="-1 0 0"/>
    <limit effort="1000" lower="-0.10" upper="3.14" velocity="5.8"/>
    <origin rpy="0.20 0 0" xyz="0.0 0.035 0.085"/>
    <parent link="right_arm_gripper_body_link"/>
    <child link="right_arm_gripper_finger_link2"/>
  </joint>
  <link name="right_arm_gripper_finger_link2">
    <visual>
      <origin rpy="0.0 0.0 0.0" xyz="0 0.020 0.08"/>
      <geometry>
        <box size="0.02 0.02 0.08"/>
      </geometry>
      <material name="Mustard"/>
    </visual>
    <collision>
      <origin rpy="0.0 0.0 0.0" xyz="0 0.020 0.08"/>
      <geometry>
        <box size="0.02 0.02 0.08"/>
      </geometry>
    </collision>
  </link>
  <!-- Planning link and joint for the gripper -->
  <joint name="right_arm_gripper_joint" type="fixed">
    <origin rpy="0 1.570795 0" xyz="0 0 0.21"/>
    <axis xyz="0 0 1"/>
    <parent link="right_arm_gripper_body_link"/>
    <child link="right_arm_gripper_link"/>
  </joint>
  <link name="right_arm_gripper_link">
    <visual>
      <origin rpy="0 0 0" xyz="0 0 0"/>
      <geometry>
        <box size="0.001 0.0005 0.0005"/>
      </geometry>
      <material name="Orange"/>
    </visual>
  </link>
  <link name="left_arm_torso_link"/>
  <joint name="left_arm_torso_joint" type="fixed">
    <origin rpy="0 0 0" xyz="0.0 0.164 0.389"/>
    <parent link="torso_link"/>
    <child link="left_arm_torso_link"/>
  </joint>
  <joint name="left_arm_shoulder_rotate_servo_joint" type="fixed">
    <origin rpy="0.0 -1.57 0" xyz="0 0 0"/>
    <parent link="left_arm_torso_link"/>
    <child link="left_arm_shoulder_rotate_servo_link"/>
  </joint>
  <link name="left_arm_shoulder_rotate_servo_link">
    <inertial>
      <mass value="0.00001"/>
      <origin xyz="0 0 0"/>
      <inertia ixx="1.0" ixy="0.0" ixz="0.0" iyy="1.0" iyz="0.0" izz="1.0"/>
    </inertial>
    <visual>
      <origin rpy="1.57 1.57 0" xyz=" 0 0 0 "/>
      <geometry>
        <mesh filename="package://sheldon_description/meshes/rx64.stl" scale="1 1 1"/>
      </geometry>
      <material name="Green"/>
    </visual>
    <collision>
      <origin rpy="0 0 0" xyz="-0.01755 0 0"/>
      <geometry>
        <box size="0.0611 0.0470 0.0420"/>
      </geometry>
    </collision>
  </link>
  <joint name="left_arm_shoulder_rotate_joint" type="revolute">
    <origin rpy="-1.57 0 1.57" xyz="0 0 0"/>
    <axis xyz="-1 0 0"/>
    <limit effort="1000" lower="-3.14" upper="3.14" velocity="2.3"/>
    <parent link="left_arm_shoulder_rotate_servo_link"/>
    <child link="left_arm_shoulder_rotate_link"/>
  </joint>
  <link name="left_arm_shoulder_rotate_link">
    <inertial>
      <mass value="0.00001"/>
      <origin xyz="0 0 0"/>
      <inertia ixx="1.0" ixy="0.0" ixz="0.0" iyy="1.0" iyz="0.0" izz="1.0"/>
    </inertial>
    <visual>
      <origin rpy="-1.57 0 3.14" xyz="0.0869955 0 0"/>
      <geometry>
        <mesh filename="package://sheldon_description/meshes/sixdof_bracket2.stl" scale="0.001 0.001 0.001"/>
      </geometry>
      <material name="Grey"/>
    </visual>
    <collision>
      <origin rpy="0 0 0" xyz="0.0381 0.0 0.0"/>
      <geometry>
        <box size="0.0762 0.053 0.044"/>
      </geometry>
    </collision>
  </link>
  <!-- Shoulder Lift -->
  <joint name="left_arm_shoulder_lift_joint" type="revolute">
    <origin rpy="0 0 0" xyz="0.0869955 0 0"/>
    <axis xyz="0 1 0"/>
    <limit effort="1000" lower="-0.050" upper="2.10" velocity="4.6"/>
    <parent link="left_arm_shoulder_rotate_link"/>
    <child link="left_arm_shoulder_lift_servo_link"/>
  </joint>
  <link name="left_arm_shoulder_lift_servo_link">
    <inertial>
      <mass value="0.00001"/>
      <origin xyz="0 0 0"/>
      <inertia ixx="1.0" ixy="0.0" ixz="0.0" iyy="1.0" iyz="0.0" izz="1.0"/>
    </inertial>
    <visual>
      <origin rpy="1.57 -3.14 0" xyz=" 0 0 0 "/>
      <!-- rpy="1.57 -1.57 0" or -3.14 -->
      <geometry>
        <mesh filename="package://sheldon_description/meshes/rx64.stl" scale="1 1 1"/>
      </geometry>
      <material name="Green"/>
    </visual>
    <collision>
      <origin rpy="0 0 0" xyz="0.01755 0 0"/>
      <geometry>
        <box size="0.0611 0.0470 0.0420"/>
      </geometry>
    </collision>
  </link>
  <!-- Upper Arm fixed link -->
  <joint name="left_arm_upper_fixed_joint" type="fixed">
    <origin rpy="0 -1.57 0" xyz="0 0 0"/>
    <parent link="left_arm_shoulder_lift_servo_link"/>
    <child link="left_arm_upper_link"/>
  </joint>
  <link name="left_arm_upper_link">
    <inertial>
      <mass value="0.00001"/>
      <origin xyz="0 0 0"/>
      <inertia ixx="1.0" ixy="0.0" ixz="0.0" iyy="1.0" iyz="0.0" izz="1.0"/>
    </inertial>
    <visual>
      <origin rpy="0 1.57 3.14" xyz="0 0 0"/>
      <geometry>
        <mesh filename="package://sheldon_description/meshes/sheldon_left_arm_upper.stl" scale="0.1 0.1 0.1"/>
      </geometry>
      <material name="Mustard"/>
    </visual>
    <collision>
      <origin rpy="0 0 0" xyz="0.1925 0 0 "/>
      <geometry>
        <box size="0.305 0.09 0.09"/>
      </geometry>
    </collision>
  </link>
  <joint name="left_arm_elbow_rotate_servo_joint" type="fixed">
    <origin rpy="-1.57 3.14 -1.57" xyz="0.335 0.015 0"/>
    <parent link="left_arm_upper_link"/>
    <child link="left_arm_elbow_rotate_servo_link"/>
  </joint>
  <link name="left_arm_elbow_rotate_servo_link">
    <inertial>
      <mass value="0.00001"/>
      <origin xyz="0 0 0"/>
      <inertia ixx="1.0" ixy="0.0" ixz="0.0" iyy="1.0" iyz="0.0" izz="1.0"/>
    </inertial>
    <visual>
      <origin rpy="0 0 -1.57" xyz=" 0 0 0 "/>
      <geometry>
        <mesh filename="package://sheldon_description/meshes/rx64.stl" scale="1 1 1"/>
      </geometry>
      <material name="Blue"/>
    </visual>
    <collision>
      <origin rpy="0 0 0" xyz="-0.01755 0.0 0"/>
      <geometry>
        <box size="0.0611 0.0420 0.0470"/>
      </geometry>
    </collision>
  </link>
  <joint name="left_arm_elbow_rotate_joint" type="revolute">
    <origin rpy="0 0 0" xyz="0 0 0.0235"/>
    <axis xyz="0 0 -1"/>
    <limit effort="1000" lower="-2.2" upper="3.14" velocity="6.6"/>
    <parent link="left_arm_elbow_rotate_servo_link"/>
    <child link="left_arm_elbow_rotate_link"/>
  </joint>
  <link name="left_arm_elbow_rotate_link">
    <inertial>
      <mass value="0.00001"/>
      <origin xyz="0 0 0"/>
      <inertia ixx="1.0" ixy="0.0" ixz="0.0" iyy="1.0" iyz="0.0" izz="1.0"/>
    </inertial>
    <visual>
      <origin rpy="1.57 0 0" xyz=" 0 0 0 "/>
      <geometry>
        <mesh filename="package://sheldon_description/meshes/rx64-side-bracket.stl" scale="1 1 1"/>
      </geometry>
      <material name="Grey"/>
    </visual>
    <collision>
      <origin rpy="0 0 0" xyz="0.000 0 0.005"/>
      <geometry>
        <box size="0.037 0.037 0.010"/>
      </geometry>
    </collision>
  </link>
  <joint name="left_arm_elbow_bend_servo_joint" type="fixed">
    <origin rpy="0 -1.57 0" xyz="0 0 0.0526"/>
    <parent link="left_arm_elbow_rotate_link"/>
    <child link="left_arm_elbow_bend_servo_link"/>
  </joint>
  <link name="left_arm_elbow_bend_servo_link">
    <inertial>
      <mass value="0.00001"/>
      <origin xyz="0 0 0"/>
      <inertia ixx="1.0" ixy="0.0" ixz="0.0" iyy="1.0" iyz="0.0" izz="1.0"/>
    </inertial>
    <visual>
      <origin rpy="1.57 1.57 0" xyz=" 0 0 0 "/>
      <geometry>
        <mesh filename="package://sheldon_description/meshes/rx64.stl" scale="1 1 1"/>
      </geometry>
      <material name="Green"/>
    </visual>
    <collision>
      <origin rpy="0 0 0" xyz="-0.01755 0 0"/>
      <geometry>
        <box size="0.0611 0.0470 0.0420"/>
      </geometry>
    </collision>
  </link>
  <joint name="left_arm_elbow_bend_joint" type="revolute">
    <origin rpy="0 0 0" xyz="0 0 0.0"/>
    <axis xyz="0 1 0"/>
    <limit effort="1000" lower="-1.2" upper="3.14" velocity="6.6"/>
    <parent link="left_arm_elbow_bend_servo_link"/>
    <child link="left_arm_elbow_bend_link"/>
  </joint>
  <link name="left_arm_elbow_bend_link">
    <inertial>
      <mass value="0.00001"/>
      <origin xyz="0 0 0"/>
      <inertia ixx="1.0" ixy="0.0" ixz="0.0" iyy="1.0" iyz="0.0" izz="1.0"/>
    </inertial>
    <visual>
      <origin rpy="0 0 -1.57" xyz="0 0 0"/>
      <geometry>
        <mesh filename="package://sheldon_description/meshes/rx64-hinge-bracket.stl" scale="1 1 1"/>
      </geometry>
      <material name="Grey"/>
    </visual>
    <collision>
      <origin rpy="0 0 0" xyz="0.015 0.0 0.0"/>
      <geometry>
        <box size="0.030 0.056 0.031"/>
      </geometry>
    </collision>
  </link>
  <!-- Lower Arm fixed link -->
  <joint name="left_arm_lower_fixed_joint" type="fixed">
    <!--  "0.030 0 0.031" half the length, plus bracket lenth and offset -->
    <origin rpy="0 1.57 0" xyz="0.030 0 0.031"/>
    <!-- KLUDGE FOR TESTING!!! -->
    <parent link="left_arm_elbow_bend_link"/>
    <child link="left_arm_lower_link"/>
  </joint>
  <link name="left_arm_lower_link">
    <inertial>
      <mass value="0.00001"/>
      <origin xyz="0 0 0"/>
      <inertia ixx="1.0" ixy="0.0" ixz="0.0" iyy="1.0" iyz="0.0" izz="1.0"/>
    </inertial>
    <visual>
      <origin rpy="0 0 0" xyz="0 0 0.0765"/>
      <!-- rpy="-1.57 0 0" -->
      <geometry>
        <!-- TODO: <mesh filename="package://sheldon_description/meshes/sheldon_${side}_lower.stl" scale="0.1 0.1 0.1"/> -->
        <box size="0.04 0.06 0.153"/>
      </geometry>
      <material name="Yellow"/>
    </visual>
    <collision>
      <origin rpy="0 0 0" xyz="0 0 0.0765"/>
      <!-- rpy="-1.57 0 0"   divide a little more then 1/2 for collision-->
      <geometry>
        <box size="0.04 0.06 0.1377"/>
      </geometry>
    </collision>
  </link>
  <joint name="left_arm_wrist_bend_servo_joint" type="fixed">
    <origin rpy="0 -1.57 0" xyz="0 0 0.1705"/>
    <parent link="left_arm_lower_link"/>
    <child link="left_arm_wrist_bend_servo_link"/>
  </joint>
  <link name="left_arm_wrist_bend_servo_link">
    <inertial>
      <mass value="0.00001"/>
      <origin xyz="0 0 0"/>
      <inertia ixx="1.0" ixy="0.0" ixz="0.0" iyy="1.0" iyz="0.0" izz="1.0"/>
    </inertial>
    <visual>
      <origin rpy="1.57 1.57 0" xyz=" 0 0 0 "/>
      <geometry>
        <mesh filename="package://sheldon_description/meshes/rx28.stl" scale="1 1 1"/>
      </geometry>
      <material name="Green"/>
    </visual>
    <collision>
      <origin rpy="0 0 0" xyz="-0.0133 0 0"/>
      <geometry>
        <box size="0.0506 0.045 0.0356"/>
      </geometry>
    </collision>
  </link>
  <joint name="left_arm_wrist_bend_joint" type="revolute">
    <origin rpy="0 0 0" xyz="0 0 0.0"/>
    <axis xyz="0 1 0"/>
    <limit effort="1000" lower="-1.57" upper="1.57" velocity="6.6"/>
    <parent link="left_arm_wrist_bend_servo_link"/>
    <child link="left_arm_wrist_bend_link"/>
  </joint>
  <link name="left_arm_wrist_bend_link">
    <inertial>
      <mass value="0.00001"/>
      <origin xyz="0 0 0"/>
      <inertia ixx="1.0" ixy="0.0" ixz="0.0" iyy="1.0" iyz="0.0" izz="1.0"/>
    </inertial>
    <visual>
      <origin rpy="0 0 -1.57" xyz="0 0 0"/>
      <geometry>
        <mesh filename="package://sheldon_description/meshes/rx28-hinge-bracket.stl" scale="1 1 1"/>
      </geometry>
      <material name="Grey"/>
    </visual>
    <collision>
      <origin rpy="0 0 0" xyz="0.015 0.0 0.0"/>
      <geometry>
        <box size="0.030 0.045 0.031"/>
      </geometry>
    </collision>
  </link>
  <joint name="left_arm_wrist_rotate_servo_joint" type="fixed">
    <origin rpy="3.14 -1.57 0" xyz="0.0475 0 0"/>
    <parent link="left_arm_wrist_bend_link"/>
    <child link="left_arm_wrist_rotate_servo_link"/>
  </joint>
  <link name="left_arm_wrist_rotate_servo_link">
    <inertial>
      <mass value="0.00001"/>
      <origin xyz="0 0 0"/>
      <inertia ixx="1.0" ixy="0.0" ixz="0.0" iyy="1.0" iyz="0.0" izz="1.0"/>
    </inertial>
    <visual>
      <origin rpy="0 0 -1.57" xyz=" 0 0 0 "/>
      <geometry>
        <mesh filename="package://sheldon_description/meshes/rx28.stl" scale="1 1 1"/>
      </geometry>
      <material name="Green"/>
    </visual>
    <collision>
      <origin rpy="0 0 0" xyz="-0.0133 0.0 0"/>
      <geometry>
        <box size="0.0506 0.045 0.0356"/>
      </geometry>
    </collision>
  </link>
  <joint name="left_arm_wrist_rotate_joint" type="revolute">
    <origin rpy="0 0 0" xyz="0 0 0"/>
    <axis xyz="0 0 -1"/>
    <limit effort="1000" lower="-3.0" upper="1.57" velocity="5.8"/>
    <parent link="left_arm_wrist_rotate_servo_link"/>
    <child link="left_arm_wrist_rotate_link"/>
  </joint>
  <link name="left_arm_wrist_rotate_link">
    <inertial>
      <mass value="0.00001"/>
      <origin xyz="0 0 0"/>
      <inertia ixx="1.0" ixy="0.0" ixz="0.0" iyy="1.0" iyz="0.0" izz="1.0"/>
    </inertial>
    <visual>
      <origin rpy="1.57 0 0" xyz=" 0 0 0 "/>
      <geometry>
        <mesh filename="package://sheldon_description/meshes/rx28-side-bracket.stl" scale="1 1 1"/>
      </geometry>
      <material name="Grey"/>
    </visual>
    <collision>
      <origin rpy="0 0 0" xyz="0.005 0 0.005"/>
      <geometry>
        <box size="0.010 0.037 0.037"/>
      </geometry>
    </collision>
  </link>
  <!-- Gripper fixed joint -->
  <joint name="left_arm_gripper_fixed_joint" type="fixed">
    <origin rpy="0 0 0" xyz="0 0 0"/>
    <!-- "0 0.03 0" -->
    <parent link="left_arm_wrist_rotate_link"/>
    <child link="left_arm_gripper_body_link"/>
  </joint>
  <!-- Gripper body fixed link -->
  <link name="left_arm_gripper_body_link">
    <inertial>
      <mass value="0.00001"/>
      <origin xyz="0 0 0"/>
      <inertia ixx="1.0" ixy="0.0" ixz="0.0" iyy="1.0" iyz="0.0" izz="1.0"/>
    </inertial>
    <visual>
      <origin rpy="0 0 0" xyz="0 0 0"/>
      <!-- rpy="-1.57 0 0" -->
      <geometry>
        <mesh filename="package://sheldon_description/meshes/sheldon_claw.stl" scale="0.1 0.1 0.1"/>
        <!-- <box size="0.05 0.12 0.215"/> -->
      </geometry>
      <material name="Purple"/>
    </visual>
    <collision>
      <origin rpy="0 0 0" xyz="0 0 0.1075"/>
      <!-- rpy="-1.57 0 0" -->
      <geometry>
        <box size="0.05 0.09 0.170"/>
      </geometry>
    </collision>
  </link>
  <!-- Finger Rotate -->
  <joint name="left_arm_gripper_finger_joint" type="revolute">
    <axis xyz="1 0 0"/>
    <limit effort="1000" lower="-0.10" upper="3.14" velocity="5.8"/>
    <origin rpy="-0.20 0 0" xyz="0.0 -0.035 0.085"/>
    <parent link="left_arm_gripper_body_link"/>
    <child link="left_arm_gripper_finger_link1"/>
  </joint>
  <link name="left_arm_gripper_finger_link1">
    <visual>
      <origin rpy="0.0 0.0 0.0" xyz="0 -0.020 0.08"/>
      <geometry>
        <box size="0.02 0.02 0.08"/>
      </geometry>
      <material name="Mustard"/>
    </visual>
    <collision>
      <origin rpy="0.0 0.0 0.0" xyz="0 -0.020 0.08"/>
      <geometry>
        <box size="0.02 0.02 0.08"/>
      </geometry>
    </collision>
  </link>
  <joint name="left_arm_gripper_finger_joint2" type="revolute">
    <mimic joint="left_arm_gripper_finger_joint"/>
    <axis xyz="-1 0 0"/>
    <limit effort="1000" lower="-0.10" upper="3.14" velocity="5.8"/>
    <origin rpy="0.20 0 0" xyz="0.0 0.035 0.085"/>
    <parent link="left_arm_gripper_body_link"/>
    <child link="left_arm_gripper_finger_link2"/>
  </joint>
  <link name="left_arm_gripper_finger_link2">
    <visual>
      <origin rpy="0.0 0.0 0.0" xyz="0 0.020 0.08"/>
      <geometry>
        <box size="0.02 0.02 0.08"/>
      </geometry>
      <material name="Mustard"/>
    </visual>
    <collision>
      <origin rpy="0.0 0.0 0.0" xyz="0 0.020 0.08"/>
      <geometry>
        <box size="0.02 0.02 0.08"/>
      </geometry>
    </collision>
  </link>
  <!-- Planning link and joint for the gripper -->
  <joint name="left_arm_gripper_joint" type="fixed">
    <origin rpy="0 1.570795 0" xyz="0 0 0.21"/>
    <axis xyz="0 0 1"/>
    <parent link="left_arm_gripper_body_link"/>
    <child link="left_arm_gripper_link"/>
  </joint>
  <link name="left_arm_gripper_link">
    <visual>
      <origin rpy="0 0 0" xyz="0 0 0"/>
      <geometry>
        <box size="0.001 0.0005 0.0005"/>
      </geometry>
      <material name="Orange"/>
    </visual>
  </link>
  <!-- Attach the right gripper 
   <gripper side="right" reflect="-1" parent="right_arm_gripper_attach" color="Green">
     <origin xyz="0 0 0" rpy="0 0 0" /> 
   </gripper> -->
  <!-- Attach the left gripper 
   <gripper side="left" reflect="1" parent="left_arm_gripper_attach" color="Green">
     <origin xyz="0 0 0" rpy="0 0 0" /> 
   </gripper> -->
</robot>

